Workbook
Name Excel_BuiltIn_Print_Area_1: #REF!
Name Excel_BuiltIn_Print_Area_1: #REF!
Name Excel_BuiltIn_Print_Area_1: #REF!
Name Excel_BuiltIn_Print_Area_3: #REF!
Name Excel_BuiltIn_Print_Area_3: #REF!
Name Excel_BuiltIn_Print_Area_3: #REF!

Sheet 12_21
A1: 0 | B1: tm | C1: CodCli | D1: Nome | E1: dtvcto | F1: Valor | G1: tipo | H1: Pagto.
C2: SOCIOS | D2: SEGURO DE VIDA RUBENS c | E2: 44531 | F2: 1020 | G2: Distribuição de Lucros | H2: =VLOOKUP(E2,$E$2783:$H$2814,4,FALSE) -> 44531
C3: EPI | D3: ZAPA | E3: 44531 | F3: 1043.68 | G3: Empresa 2 | H3: =VLOOKUP(E3,$E$2783:$H$2814,4,FALSE) -> 44531
C4: ENERGIA | D4: RGE | E4: 44532 | F4: 1000 | G4: Empresa 1 | H4: =VLOOKUP(E4,$E$2783:$H$2814,4,FALSE) -> 44532
C5: SALARIOS | D5: SALARIOS | E5: 44532 | F5: 6000 | G5: Empresa 1 | H5: =VLOOKUP(E5,$E$2783:$H$2814,4,FALSE) -> 44532
C6: SALARIOS | D6: SALARIOS | E6: 44532 | F6: 90000 | G6: Empresa 2 | H6: =VLOOKUP(E6,$E$2783:$H$2814,4,FALSE) -> 44532
C7: SOCIOS | D7: RETIRADA LUIS b | E7: 44532 | F7: 2500 | G7: Distribuição de Lucros | H7: =VLOOKUP(E7,$E$2783:$H$2814,4,FALSE) -> 44532
C8: SOCIOS | D8: RETIRADA PAULO d | E8: 44532 | F8: 2000 | G8: Distribuição de Lucros | H8: =VLOOKUP(E8,$E$2783:$H$2814,4,FALSE) -> 44532
C9: ACORDO | D9: LEONARDO - CIFERAL - 11/14 | E9: 44533 | F9: 1500 | G9: Empresa 2 | H9: =VLOOKUP(E9,$E$2783:$H$2814,4,FALSE) -> 44533
C10: EPI | D10: JUSTINA | E10: 44533 | F10: 900 | G10: Empresa 2 | H10: =VLOOKUP(E10,$E$2783:$H$2814,4,FALSE) -> 44533
C11: PARCELAMENTO | D11: EMPRESTIMO FOLHA BB - 12/30 | E11: 44533 | F11: 2090.64 | G11: Empresa 2 | H11: =VLOOKUP(E11,$E$2783:$H$2814,4,FALSE) -> 44533
C12: PARCELAMENTO | D12: EMPRESTIMO FOLHA BB - 13/30 | E12: 44534 | F12: 2008.11 | G12: Empresa 2 | H12: =VLOOKUP(E12,$E$2783:$H$2814,4,FALSE) -> 44536
C13: FÉRIAS | D13: CLEBER MELLO - vcto 01/11 - não tem salario | E13: 44535 | F13: 5953 | G13: Empresa 2 | H13: =VLOOKUP(E13,$E$2783:$H$2814,4,FALSE) -> 44536
... C69: PARCELAMENTO | D69: CSLL - DEBITO BB | E69: 44560 | F69: 526.26 | G69: Empresa 2 | H69: =VLOOKUP(E69,$E$2783:$H$2814,4,FALSE) -> 44560
D2782: CALENDÁRIO A AJUSTAR | E2782: VCTO
A2783: RELAÇÃO DAS CONTAS DO FLUXO | D2783: DIAS CORRIDOS > | E2783: 44531 | G2783: A VERIFICAR | H2783: 44531 | I2783: >>Data de Pagto
A2784: (Preenchet até a linha 2.100) | D2784: DIAS CORRIDOS > | E2784: 44532 | G2784: ALUGUEIS DEPÓSITOS PFT/GUGELMIN - MATRIZ | H2784: 44532 | I2784: >>Data de Pagto
D2785: DIAS CORRIDOS > | E2785: 44533 | G2785: ALUGUEL EQUIPAMENTOS E MÁQUINAS | H2785: 44533 | I2785: >>Data de Pagto
D2786: DIAS CORRIDOS > | E2786: 44534 | G2786: COMBUSTÍVEIS E LUBRIFICANTES | H2786: 44536 | I2786: >>Data de Pagto
D2787: DIAS CORRIDOS > | E2787: 44535 | G2787: COMISSÕES COM VENDAS | H2787: 44536 | I2787: >>Data de Pagto
D2788: DIAS CORRIDOS > | E2788: 44536 | G2788: COMPRA DE MADEIRA | H2788: 44536 | I2788: >>Data de Pagto
D2789: DIAS CORRIDOS > | E2789: 44537 | G2789: COMPRA DE TORAS | H2789: 44537 | I2789: >>Data de Pagto
D2790: DIAS CORRIDOS > | E2790: 44538 | G2790: CONTROLADORIA - W-90X | H2790: 44538 | I2790: >>Data de Pagto
D2791: DIAS CORRIDOS > | E2791: 44539 | G2791: CONTROLADORIA - À VISTA | H2791: 44539 | I2791: >>Data de Pagto
D2792: DIAS CORRIDOS > | E2792: 44540 | G2792: CONTROLADORIA - ADIANTAMENTOS | H2792: 44540 | I2792: >>Data de Pagto
D2793: DIAS CORRIDOS > | E2793: 44541 | G2793: CONTROLADORIA - FRETES INTERNACIONAIS | H2793: 44543 | I2793: >>Data de Pagto
D2794: DIAS CORRIDOS > | E2794: 44542 | G2794: CONTROLADORIA - SILVEIRA | H2794: 44543 | I2794: >>Data de Pagto
D2795: DIAS CORRIDOS > | E2795: 44543 | G2795: CREDORES DIVERSOS | H2795: 44543 | I2795: >>Data de Pagto
D2796: DIAS CORRIDOS > | E2796: 44544 | G2796: DESPESAS ADUANEIRAS | H2796: 44544 | I2796: >>Data de Pagto
... D2812: DIAS CORRIDOS > | E2812: 44560 | G2812: OPERAÇÕES DE CRÉDITO/FORNECEDOR | H2812: 44560 | I2812: >>Data de Pagto
D2813: DIAS CORRIDOS > | E2813: 44561 | H2813: 44561 | I2813: >>Data de Pagto
D2814: SÁBADOS E DOMINGOS > | E2814: 44534 | G2814: OPERAÇÕES FINANCEIRAS DIVS. | H2814: 44534
D2815: SÁBADOS E DOMINGOS > | E2815: 44535 | G2815: PRESTAÇÃO DE SERVIÇOS E ASESSORIAS | H2815: 44535
D2816: SÁBADOS E DOMINGOS > | E2816: 44541 | G2816: PRIME RIBAS | H2816: 44541
D2817: SÁBADOS E DOMINGOS > | E2817: 44542 | G2817: PRIME RIBAS PREVISTO | H2817: 44542
D2818: SÁBADOS E DOMINGOS > | E2818: 44548 | G2818: PROGRAMAS ESPECIAIS | H2818: 44548
D2819: SÁBADOS E DOMINGOS > | E2819: 44549 | G2819: SALÁRIOS + ASSESSORIA DIRETA + BENEFÍCIOS | H2819: 44549
D2820: SÁBADOS E DOMINGOS > | E2820: 44555 | G2820: SERVIÇOS PÚBLICOS | H2820: 44555
D2821: SÁBADOS E DOMINGOS > | E2821: 44556 | H2821: 44556
D2822: SÁBADOS E DOMINGOS >

Sheet Fluxo_12_21
B1: =IF(B5=1,"Domingo",IF(B5=2,"Segunda",IF(B5=3,"Terça",IF(B5=4,"Quarta",IF(B5=5,"Quinta",IF(B5=6,"Sexta",IF(B5=7,"Sábado",0))))))) -> Quarta | C1: =IF(C5=1,"Domingo",IF(C5=2,"Segunda",IF(C5=3,"Terça",IF(C5=4,"Quarta",IF(C5=5,"Quinta",IF(C5=6,"Sexta",IF(C5=7,"Sábado",0))))))) -> Quinta | D1: =IF(D5=1,"Domingo",IF(D5=2,"Segunda",IF(D5=3,"Terça",IF(D5=4,"Quarta",IF(D5=5,"Quinta",IF(D5=6,"Sexta",IF(D5=7,"Sábado",0))))))) -> Sexta | E1: =IF(E5=1,"Domingo",IF(E5=2,"Segunda",IF(E5=3,"Terça",IF(E5=4,"Quarta",IF(E5=5,"Quinta",IF(E5=6,"Sexta",IF(E5=7,"Sábado",0))))))) -> Segunda | F1: =IF(F5=1,"Domingo",IF(F5=2,"Segunda",IF(F5=3,"Terça",IF(F5=4,"Quarta",IF(F5=5,"Quinta",IF(F5=6,"Sexta",IF(F5=7,"Sábado",0))))))) -> Terça | G1: =IF(G5=1,"Domingo",IF(G5=2,"Segunda",IF(G5=3,"Terça",IF(G5=4,"Quarta",IF(G5=5,"Quinta",IF(G5=6,"Sexta",IF(G5=7,"Sábado",0))))))) -> Quarta | H1: =IF(H5=1,"Domingo",IF(H5=2,"Segunda",IF(H5=3,"Terça",IF(H5=4,"Quarta",IF(H5=5,"Quinta",IF(H5=6,"Sexta",IF(H5=7,"Sábado",0))))))) -> Quinta | I1: =IF(I5=1,"Domingo",IF(I5=2,"Segunda",IF(I5=3,"Terça",IF(I5=4,"Quarta",IF(I5=5,"Quinta",IF(I5=6,"Sexta",IF(I5=7,"Sábado",0))))))) -> Sexta | ... W1: =IF(W5=1,"Domingo",IF(W5=2,"Segunda",IF(W5=3,"Terça",IF(W5=4,"Quarta",IF(W5=5,"Quinta",IF(W5=6,"Sexta",IF(W5=7,"Sábado",0))))))) -> Quinta
A2: Localizado no banco | B2: =B29 -> 44531 | C2: =C29 -> 44532 | D2: =D29 -> 44533 | E2: =E29 -> 44536 | F2: =F29 -> 44537 | G2: =G29 -> 44538 | H2: =H29 -> 44539 | I2: =I29 -> 44540 | ... W2: =W29 -> 44560
A4: SALDO INICIAL | B4: =Fluxo_11_21!U38 -> -242393.87 | C4: =B38 -> -243413.87 | D4: =C38 -> -344913.87 | E4: =D38 -> -348504.51 | F4: =E38 -> -359194.62 | G4: =F38 -> -366194.62 | H4: =G38 -> -367698.88 | I4: =H38 -> -372198.88 | J4: =I38 -> -375198.88 | ... W4: =V38 -> -528042.39
B5: =WEEKDAY(B2) -> 4 | C5: =WEEKDAY(C2) -> 5 | D5: =WEEKDAY(D2) -> 6 | E5: =WEEKDAY(E2) -> 2 | F5: =WEEKDAY(F2) -> 3 | G5: =WEEKDAY(G2) -> 4 | H5: =WEEKDAY(H2) -> 5 | I5: =WEEKDAY(I2) -> 6 | ... W5: =WEEKDAY(W2) -> 5
A6: RECEBIMENTOS (OPERAÇÃO) | B6: =SUM(B7:B26) -> 0 | C6: =SUM(C7:C26) -> 0 | D6: =SUM(D7:D26) -> 0 | E6: =SUM(E7:E26) -> 0 | F6: =SUM(F7:F26) -> 0 | G6: =SUM(G7:G26) -> 0 | H6: =SUM(H7:H26) -> 0 | I6: =SUM(I7:I26) -> 0 | ... W6: =SUM(W7:W26) -> 0
A7: MARCOPOLO/SEMAN
A8: MARCOPOLO
A9: VOLARE
A10: HIDROVER
A11: WSUL
A12: RUGERI
A13: CIFERAL
A14: SAN MARINO
A15: LIBRELATO
A27: PAGAMENTOS PROGRAMADOS
A28: Soma de Valor | B28: Pagto.
A29: tipo | B29: 44531 | C29: 44532 | D29: 44533 | E29: 44536 | F29: 44537 | G29: 44538 | H29: 44539 | I29: 44540 | J29: 44543 | K29: 44544 | L29: 44545 | M29: 44546 | N29: 44547 | O29: 44550 | P29: 44551 | Q29: 44552 | R29: 44553 | S29: 44554 | T29: 44557 | U29: 44558 | V29: 44559 | W29: 44560 | X29: Total Geral
A30: PARTICULAR | B30: 1020 | C30: 4500 | H30: 4500 | I30: 3000 | L30: 2573.42 | M30: 4500 | N30: 246.8 | R30: 4500 | T30: 3500 | V30: 404.34 | X30: 28744.56
A31: VENTURE | C31: 7000 | F31: 1000 | J31: 14028.3 | K31: 3390 | M31: 1750 | N31: 4000 | O31: 2800 | P31: 444.18 | V31: 2500 | X31: 36912.48
A32: SOLUTEC | L32: 1843 | S32: 500 | X32: 2343
A33: PKS | L33: 3594.05 | X33: 3594.05
A34: SEMAN | C34: 90000 | D34: 3590.64 | E34: 10690.11 | F34: 6000 | G34: 1504.26 | J34: 7653.5 | L34: 2305 | N34: 51096.62 | O34: 18985.91 | P34: 1500 | Q34: 6500 | T34: 1995 | U34: 11733.39 | V34: 500 | W34: 2412.66 | X34: 216467.09
A35: Total Geral | B35: 1020 | C35: 101500 | D35: 3590.64 | E35: 10690.11 | F35: 7000 | G35: 1504.26 | H35: 4500 | I35: 3000 | J35: 21681.8 | K35: 3390 | L35: 10315.47 | M35: 6250 | N35: 55343.42 | O35: 21785.91 | P35: 1944.18 | Q35: 6500 | R35: 4500 | S35: 500 | T35: 5495 | U35: 11733.39 | V35: 3404.34 | W35: 2412.66 | X35: 288061.18
B38: =B4+B6-GETPIVOTDATA("Valor",$A$28,"Pagto.",DATE(2021,12,1)) -> -243413.87 | C38: =C4+C6-GETPIVOTDATA("Valor",$A$28,"Pagto.",DATE(2021,12,2)) -> -344913.87 | D38: =D4+D6-GETPIVOTDATA("Valor",$A$28,"Pagto.",DATE(2021,12,3)) -> -348504.51 | E38: =E4+E6-GETPIVOTDATA("Valor",$A$28,"Pagto.",DATE(2021,12,6)) -> -359194.62 | F38: =F4+F6-GETPIVOTDATA("Valor",$A$28,"Pagto.",DATE(2021,12,7)) -> -366194.62 | G38: =G4+G6-GETPIVOTDATA("Valor",$A$28,"Pagto.",DATE(2021,12,8)) -> -367698.88 | H38: =H4+H6-GETPIVOTDATA("Valor",$A$28,"Pagto.",DATE(2021,12,9)) -> -372198.88 | I38: =I4+I6-GETPIVOTDATA("Valor",$A$28,"Pagto.",DATE(2021,12,10)) -> -375198.88 | J38: =J4+J6-GETPIVOTDATA("Valor",$A$28,"Pagto.",DATE(2021,12,13)) -> -396880.68 | K38: =K4+K6-GETPIVOTDATA("Valor",$A$28,"Pagto.",DATE(2021,12,14)) -> -400270.68 | L38: =L4+L6-GETPIVOTDATA("Valor",$A$28,"Pagto.",DATE(2021,12,15)) -> -410586.15 | M38: =M4+M6-GETPIVOTDATA("Valor",$A$28,"Pagto.",DATE(2021,12,16)) -> -416836.15 | N38: =N4+N6-GETPIVOTDATA("Valor",$A$28,"Pagto.",DATE(2021,12,17)) -> -472179.57 | O38: =O4+O6-GETPIVOTDATA("Valor",$A$28,"Pagto.",DATE(2021,12,20)) -> -493965.48 | P38: =P4+P6-GETPIVOTDATA("Valor",$A$28,"Pagto.",DATE(2021,12,21)) -> -495909.66 | Q38: =Q4+Q6-GETPIVOTDATA("Valor",$A$28,"Pagto.",DATE(2021,12,22)) -> -502409.66 | R38: =R4+R6-GETPIVOTDATA("Valor",$A$28,"Pagto.",DATE(2021,12,23)) -> -506909.66 | S38: =S4+S6-GETPIVOTDATA("Valor",$A$28,"Pagto.",DATE(2021,12,24)) -> -507409.66 | T38: =T4+T6-GETPIVOTDATA("Valor",$A$28,"Pagto.",DATE(2021,12,27)) -> -512904.66 | U38: =U4+U6-GETPIVOTDATA("Valor",$A$28,"Pagto.",DATE(2021,12,28)) -> -524638.05 | V38: =V4+V6-GETPIVOTDATA("Valor",$A$28,"Pagto.",DATE(2021,12,29)) -> -528042.39 | W38: =W4+W6-GETPIVOTDATA("Valor",$A$28,"Pagto.",DATE(2021,12,30)) -> -530455.05

Sheet 11_21
A1: 0 | B1: tm | C1: CodCli | D1: Nome | E1: dtvcto | F1: Valor | G1: tipo | H1: Pagto.
C2: BANCOS | D2: JUROS E DESPESAS BANCARIAS | E2: 44501 | F2: =2193.19 -> 2193.19 | G2: Empresa 1 | H2: =VLOOKUP(E2,$E$2868:$H$2997,4,FALSE) -> 44501
C3: ENCARGOS | D3: FGTS - vcto 07/10 | E3: 44502 | F3: =10279.79 -> 10279.79 | G3: Empresa 2 | H3: =VLOOKUP(E3,$E$2868:$H$2997,4,FALSE) -> 44503
C4: COMBUSTIVEL | D4: CLEBER | E4: 44503 | F4: 200 | G4: Empresa 2 | H4: =VLOOKUP(E4,$E$2868:$H$2997,4,FALSE) -> 44503
C5: RESCISAO | D5: ANGELICA ALVANOZ - vcto 21/10 | E5: 44504 | F5: 569.3 | G5: Empresa 2 | H5: =VLOOKUP(E5,$E$2868:$H$2997,4,FALSE) -> 44504
C6: PARCELAMENTO | D6: EMPRESTIMO FOLHA BB - 11/30 | E6: 44504 | F6: 2262.99 | G6: Empresa 2 | H6: =VLOOKUP(E6,$E$2868:$H$2997,4,FALSE) -> 44504
C7: SEGURO | D7: ROGERIO - 01/07 - ultimo prazo | E7: 44504 | F7: 404.41 | G7: Distribuição de Lucros | H7: =VLOOKUP(E7,$E$2868:$H$2997,4,FALSE) -> 44504
C8: TRANSPORTE | D8: VAN | E8: 44505 | F8: 3000 | G8: Empresa 2 | H8: =VLOOKUP(E8,$E$2868:$H$2997,4,FALSE) -> 44505
C9: VIAGEM | D9: CAIXINHA MARCIO | E9: 44505 | F9: 300 | G9: Empresa 2 | H9: =VLOOKUP(E9,$E$2868:$H$2997,4,FALSE) -> 44505
C10: VIAGEM | D10: CAIXINHA JOEL | E10: 44505 | F10: 3000 | G10: Empresa 2 | H10: =VLOOKUP(E10,$E$2868:$H$2997,4,FALSE) -> 44505
C11: SALARIOS | D11: LIBRELATO | E11: 44505 | F11: 8594 | G11: Empresa 2 | H11: =VLOOKUP(E11,$E$2868:$H$2997,4,FALSE) -> 44505
C12: SALARIOS | D12: VOLARE | E12: 44505 | F12: 14345 | G12: Empresa 2 | H12: =VLOOKUP(E12,$E$2868:$H$2997,4,FALSE) -> 44505
C13: RESCISAO | D13: ROSANGELA PEDRO - Librelato - vcto 19/10 | E13: 44505 | F13: 356.93 | G13: Empresa 2 | H13: =VLOOKUP(E13,$E$2868:$H$2997,4,FALSE) -> 44505
C14: MATERIAL | D14: CELETRO - ZANOL - vcto 19/07 - já prorrogado duas vezes | E14: 44505 | F14: 940.68 | G14: Empresa 1 | H14: =VLOOKUP(E14,$E$2868:$H$2997,4,FALSE) -> 44505
C15: TRANSPORTE | D15: VISATE - 15 CARTOES | E15: 44505 | F15: 285 | G15: Empresa 2 | H15: =VLOOKUP(E15,$E$2868:$H$2997,4,FALSE) -> 44505
C16: SALARIOS | D16: CHEQUES SALARIOS | E16: 44506 | F16: =4218+470 -> 4688 | G16: Empresa 2 | H16: =VLOOKUP(E16,$E$2868:$H$2997,4,FALSE) -> 44508
C17: PARCELAMENTO | D17: SIMPLES - 02/60 - vcto 29/10 | E17: 44506 | F17: =12064.5+527.24 -> 12591.74 | G17: Empresa 2 | H17: =VLOOKUP(E17,$E$2868:$H$2997,4,FALSE) -> 44508
C18: SAUDE | D18: UNIMED - vcto 15/10 - REEMBOLSAR SR.RUBENS | E18: 44506 | F18: 3812.48 | G18: PKS | H18: =VLOOKUP(E18,$E$2868:$H$2997,4,FALSE) -> 44508
C19: PARCELAMENTO | D19: EMPRESTIMO FOLHA BB - 12/30 | E19: 44506 | F19: 2175.1 | G19: Empresa 2 | H19: =VLOOKUP(E19,$E$2868:$H$2997,4,FALSE) -> 44508
C20: FÉRIAS | D20: ALUISIO COSTA SALES - vcto 15/10 - metade | E20: 44506 | F20: 701 | G20: Empresa 2 | H20: =VLOOKUP(E20,$E$2868:$H$2997,4,FALSE) -> 44508
C21: SALARIOS | D21: SALARIOS | E21: 44506 | F21: 6251 | G21: Empresa 1 | H21: =VLOOKUP(E21,$E$2868:$H$2997,4,FALSE) -> 44508
C22: SALARIOS | D22: SALARIOS | E22: 44506 | F22: =88123-4218-14345-8594-5052 -> 55914 | G22: Empresa 2 | H22: =VLOOKUP(E22,$E$2868:$H$2997,4,FALSE) -> 44508
C23: SALARIOS | D23: PAULO EDUARDO | E23: 44506 | F23: 2800 | G23: Empresa 2 | H23: =VLOOKUP(E23,$E$2868:$H$2997,4,FALSE) -> 44508
C24: SALARIOS | D24: PENSAO ALIMENTICIA | E24: 44506 | F24: =693.62+738.04 -> 1431.66 | G24: Empresa 2 | H24: =VLOOKUP(E24,$E$2868:$H$2997,4,FALSE) -> 44508
C25: FÉRIAS | D25: FABIANA SANTOS RODRIGUES | E25: 44506 | F25: 690 | G25: Empresa 2 | H25: =VLOOKUP(E25,$E$2868:$H$2997,4,FALSE) -> 44508
C26: SALARIOS | D26: GEAN / IGOR - VOLARE (aguardar autorizacao Joel) | E26: 44506 | F26: =2848+2204 -> 5052 | G26: Empresa 2 | H26: =VLOOKUP(E26,$E$2868:$H$2997,4,FALSE) -> 44508
C27: ASSESSORIA | D27: OLIVEIRA E PERES - parte | E27: 44506 | F27: 3135 | G27: Empresa 1 | H27: =VLOOKUP(E27,$E$2868:$H$2997,4,FALSE) -> 44508
C28: EPI | D28: JUSTINA | E28: 44506 | F28: 675 | G28: Empresa 2 | H28: =VLOOKUP(E28,$E$2868:$H$2997,4,FALSE) -> 44508
C29: COMUNICACAO | D29: NET - vcto 20/10/21 | E29: 44506 | F29: 235.89 | G29: Empresa 2 | H29: =VLOOKUP(E29,$E$2868:$H$2997,4,FALSE) -> 44508
C30: SOCIOS | D30: PAGLIARIN - vcto 18/10 | E30: 44506 | F30: 1943.25 | G30: Distribuição de Lucros | H30: =VLOOKUP(E30,$E$2868:$H$2997,4,FALSE) -> 44508
C31: FÉRIAS | D31: GABRIEL - PARTE (vcto 01/10/21) | E31: 44506 | F31: 4000 | G31: Empresa 2 | H31: =VLOOKUP(E31,$E$2868:$H$2997,4,FALSE) -> 44508
C32: ACORDO | D32: SINDIASSEIO - 02/03 - vcto 28/08 - pedir para Joana novo boleto | E32: 44507 | F32: 304.96 | G32: Empresa 2 | H32: =VLOOKUP(E32,$E$2868:$H$2997,4,FALSE) -> 44508
C33: ACORDO | D33: BRUNO DE SOUZA - 02/04 | E33: 44507 | F33: 1504.26 | G33: Empresa 2 | H33: =VLOOKUP(E33,$E$2868:$H$2997,4,FALSE) -> 44508
C34: TERCEIROS | D34: DIGISERVE - 03/03 | E34: 44508 | F34: 473.91 | G34: Empresa 1 | H34: =VLOOKUP(E34,$E$2868:$H$2997,4,FALSE) -> 44508
C35: TERCEIROS | D35: CHAVEIRO CASA DE PEDRA - pagar em dinheiro | E35: 44508 | F35: 40 | G35: Empresa 1 | H35: =VLOOKUP(E35,$E$2868:$H$2997,4,FALSE) -> 44508
C36: ALIMENTACAO | D36: ZAPAROLLI - vcto 01/11 | E36: 44508 | F36: 5962 | G36: Empresa 2 | H36: =VLOOKUP(E36,$E$2868:$H$2997,4,FALSE) -> 44508
C37: EPI | D37: JUSTINA | E37: 44508 | F37: 900 | G37: Empresa 2 | H37: =VLOOKUP(E37,$E$2868:$H$2997,4,FALSE) -> 44508
C38: EPI | D38: M JU - vcto 13/10 (prorrogado duas vezes) | E38: 44509 | F38: 966.9 | G38: Empresa 2 | H38: =VLOOKUP(E38,$E$2868:$H$2997,4,FALSE) -> 44509
... C44: SOCIOS | D44: RETIRADA ROGERIO | E44: 44510 | F44: 3000 | G44: Distribuição de Lucros | H44: =VLOOKUP(E44,$E$2868:$H$2997,4,FALSE) -> 44510
C45: COMUNICACAO | D45: CLARO - vcto 20/10/21 (corte em 13/11) | E45: 44511 | F45: =189.16+42.98+1278.98 -> 1511.12 | G45: Empresa 1 | H45: =VLOOKUP(E45,$E$2868:$H$2997,4,FALSE) -> 44511
...

Sheet Fluxo_11_21
B1: =IF(B5=1,"Domingo",IF(B5=2,"Segunda",IF(B5=3,"Terça",IF(B5=4,"Quarta",IF(B5=5,"Quinta",IF(B5=6,"Sexta",IF(B5=7,"Sábado",0))))))) -> Segunda | C1: =IF(C5=1,"Domingo",IF(C5=2,"Segunda",IF(C5=3,"Terça",IF(C5=4,"Quarta",IF(C5=5,"Quinta",IF(C5=6,"Sexta",IF(C5=7,"Sábado",0))))))) -> Quarta | D1: =IF(D5=1,"Domingo",IF(D5=2,"Segunda",IF(D5=3,"Terça",IF(D5=4,"Quarta",IF(D5=5,"Quinta",IF(D5=6,"Sexta",IF(D5=7,"Sábado",0))))))) -> Quinta | E1: =IF(E5=1,"Domingo",IF(E5=2,"Segunda",IF(E5=3,"Terça",IF(E5=4,"Quarta",IF(E5=5,"Quinta",IF(E5=6,"Sexta",IF(E5=7,"Sábado",0))))))) -> Sexta | F1: =IF(F5=1,"Domingo",IF(F5=2,"Segunda",IF(F5=3,"Terça",IF(F5=4,"Quarta",IF(F5=5,"Quinta",IF(F5=6,"Sexta",IF(F5=7,"Sábado",0))))))) -> Segunda | G1: =IF(G5=1,"Domingo",IF(G5=2,"Segunda",IF(G5=3,"Terça",IF(G5=4,"Quarta",IF(G5=5,"Quinta",IF(G5=6,"Sexta",IF(G5=7,"Sábado",0))))))) -> Terça | H1: =IF(H5=1,"Domingo",IF(H5=2,"Segunda",IF(H5=3,"Terça",IF(H5=4,"Quarta",IF(H5=5,"Quinta",IF(H5=6,"Sexta",IF(H5=7,"Sábado",0))))))) -> Quarta | I1: =IF(I5=1,"Domingo",IF(I5=2,"Segunda",IF(I5=3,"Terça",IF(I5=4,"Quarta",IF(I5=5,"Quinta",IF(I5=6,"Sexta",IF(I5=7,"Sábado",0))))))) -> Quinta | ... V1: =IF(V5=1,"Domingo",IF(V5=2,"Segunda",IF(V5=3,"Terça",IF(V5=4,"Quarta",IF(V5=5,"Quinta",IF(V5=6,"Sexta",IF(V5=7,"Sábado",0))))))) -> #VALUE!
A2: Localizado no banco | B2: =B29 -> 44501 | C2: =C29 -> 44503 | D2: =D29 -> 44504 | E2: =E29 -> 44505 | F2: =F29 -> 44508 | G2: =G29 -> 44509 | H2: =H29 -> 44510 | I2: =I29 -> 44511 | ... V2: =V29 -> Total Geral
A4: SALDO INICIAL | B4: =Fluxo_10_21!V38 -> -17062.182 | C4: =B38 -> -19255.372 | D4: =C38 -> -19619.482 | E4: =D38 -> 16045.168 | F4: =E38 -> -14776.442 | G4: =F38 -> -115327.81 | H4: =G38 -> -104115.15 | I4: =H38 -> -110649.78 | J4: =I38 -> -121403.11 | ... V4: =U38 -> -242393.87
B5: =WEEKDAY(B2) -> 2 | C5: =WEEKDAY(C2) -> 4 | D5: =WEEKDAY(D2) -> 5 | E5: =WEEKDAY(E2) -> 6 | F5: =WEEKDAY(F2) -> 2 | G5: =WEEKDAY(G2) -> 3 | H5: =WEEKDAY(H2) -> 4 | I5: =WEEKDAY(I2) -> 5 | ... V5: =WEEKDAY(V2) -> #VALUE!
A6: RECEBIMENTOS (OPERAÇÃO) | B6: =SUM(B7:B26) -> 0 | C6: =SUM(C7:C26) -> 10115.68 | D6: =SUM(D7:D26) -> 38901.35 | E6: =SUM(E7:E26) -> 0 | F6: =SUM(F7:F26) -> 14729.88 | G6: =SUM(G7:G26) -> 14579.56 | H6: =SUM(H7:H26) -> 0 | I6: =SUM(I7:I26) -> 0 | ... V6: =SUM(V7:V26) -> 0
A7: MARCOPOLO/SEMAN | D7: =6762.08+11747+14518.35 -> 33027.43 | G7: 14579.56 | K7: 14606.55
A8: MARCOPOLO | D8: =5873.92 -> 5873.92
A9: VOLARE | F9: =4850+4850 -> 9700 | K9: =648+2100+648 -> 3396 | L9: 12000
A10: HIDROVER | M10: 9172.8
A11: WSUL
A12: RUGERI | N12: 2185.89 | S12: 1749.12
A13: CIFERAL
A14: SAN MARINO | C14: =4252.83+5862.85 -> 10115.68 | F14: 5029.88 | K14: 6087.41
A15: LIBRELATO | K15: =6731.83+6201.84+5271.3 -> 18204.97 | T15: =5872.25+6946.83+5872.35+9583.14+9583.14 -> 37857.71
A27: PAGAMENTOS PROGRAMADOS
A28: Soma de Valor | B28: Pagto.
A29: tipo | B29: 44501 | C29: 44503 | D29: 44504 | E29: 44505 | F29: 44508 | G29: 44509 | H29: 44510 | I29: 44511 | J29: 44512 | K29: 44516 | L29: 44517 | M29: 44518 | N29: 44519 | O29: 44522 | P29: 44523 | Q29: 44524 | R29: 44525 | S29: 44526 | T29: 44529 | U29: 44530 | V29: Total Geral
A30: PARTICULAR | D30: 404.41 | F30: 1943.25 | H30: 3000 | I30: 4500 | J30: 1299.44 | K30: 1691.05 | M30: 4500 | N30: 246.8 | O30: 1286.71 | P30: 1020.5 | R30: 8000 | U30: 404.34 | V30: 28296.5
A31: VENTURE | B31: 2193.19 | E31: 940.68 | F31: 9899.91 | H31: 220 | I31: 1985.03 | J31: 862 | K31: 21950.79 | L31: 2369.85 | N31: 2105.8 | O31: 5084.62 | Q31: 888.36 | R31: 2576.04 | T31: 5612.5 | V31: 56688.77
A32: SOLUTEC | K32: 1476.38 | P32: 500 | V32: 1976.38
A33: PKS | F33: 3812.48 | M33: 3784.71 | R33: 3337.71 | V33: 10934.9
A34: SEMAN | C34: 10479.79 | D34: 2832.29 | E34: 29880.93 | F34: 99625.61 | G34: 3366.9 | H34: 3314.63 | I34: 4268.3 | J34: 7167.05 | K34: 10828.35 | L34: 8675.19 | M34: 3721.05 | N34: 8831.76 | O34: 27223.36 | Q34: 1643 | R34: 3946.98 | S34: 4809.19 | T34: 64072.76 | U34: 16334.92 | V34: 311022.06
A35: Total Geral | B35: 2193.19 | C35: 10479.79 | D35: 3236.7 | E35: 30821.61 | F35: 115281.25 | G35: 3366.9 | H35: 6534.63 | I35: 10753.33 | J35: 9328.49 | K35: 35946.57 | L35: 11045.04 | M35: 12005.76 | N35: 11184.36 | O35: 33594.69 | P35: 1520.5 | Q35: 2531.36 | R35: 17860.73 | S35: 4809.19 | T35: 69685.26 | U35: 16739.26 | V35: 408918.61
A38: SALDO FINAL | B38: =B4+B6-GETPIVOTDATA("Valor",$A$28,"Pagto.",DATE(2021,11,1)) -> -19255.372 | C38: =C4+C6-GETPIVOTDATA("Valor",$A$28,"Pagto.",DATE(2021,11,3)) -> -19619.482 | D38: =D4+D6-GETPIVOTDATA("Valor",$A$28,"Pagto.",DATE(2021,11,4)) -> 16045.168 | E38: =E4+E6-GETPIVOTDATA("Valor",$A$28,"Pagto.",DATE(2021,11,5)) -> -14776.442 | F38: =F4+F6-GETPIVOTDATA("Valor",$A$28,"Pagto.",DATE(2021,11,8)) -> -115327.81 | G38: =G4+G6-GETPIVOTDATA("Valor",$A$28,"Pagto.",DATE(2021,11,9)) -> -104115.15 | H38: =H4+H6-GETPIVOTDATA("Valor",$A$28,"Pagto.",DATE(2021,11,10)) -> -110649.78 | I38: =I4+I6-GETPIVOTDATA("Valor",$A$28,"Pagto.",DATE(2021,11,11)) -> -121403.11 | J38: =J4+J6-GETPIVOTDATA("Valor",$A$28,"Pagto.",DATE(2021,11,12)) -> -130731.6 | K38: =K4+K6-GETPIVOTDATA("Valor",$A$28,"Pagto.",DATE(2021,11,16)) -> -124383.24 | L38: =L4+L6-GETPIVOTDATA("Valor",$A$28,"Pagto.",DATE(2021,11,17)) -> -123428.28 | M38: =M4+M6-GETPIVOTDATA("Valor",$A$28,"Pagto.",DATE(2021,11,18)) -> -126261.24 | N38: =N4+N6-GETPIVOTDATA("Valor",$A$28,"Pagto.",DATE(2021,11,19)) -> -135259.71 | O38: =O4+O6-GETPIVOTDATA("Valor",$A$28,"Pagto.",DATE(2021,11,22)) -> -168854.4 | P38: =P4+P6-GETPIVOTDATA("Valor",$A$28,"Pagto.",DATE(2021,11,23)) -> -170374.9 | Q38: =Q4+Q6-GETPIVOTDATA("Valor",$A$28,"Pagto.",DATE(2021,11,24)) -> -172906.26 | R38: =R4+R6-GETPIVOTDATA("Valor",$A$28,"Pagto.",DATE(2021,11,25)) -> -190766.99 | S38: =S4+S6-GETPIVOTDATA("Valor",$A$28,"Pagto.",DATE(2021,11,26)) -> -193827.06 | T38: =T4+T6-GETPIVOTDATA("Valor",$A$28,"Pagto.",DATE(2021,11,29)) -> -225654.61 | U38: =U4+U6-GETPIVOTDATA("Valor",$A$28,"Pagto.",DATE(2021,11,30)) -> -242393.87

Sheet 10_21
A1: 0 | B1: tm | C1: CodCli | D1: Nome | E1: dtvcto | F1: Valor | G1: tipo | H1: Pagto.
C2: BANCOS | D2: JUROS E DESPESAS BANCARIAS | E2: 44470 | F2: =2145.17+157.32+234.5+82.75+945+430.4 -> 3995.14 | G2: Empresa 1 | H2: =VLOOKUP(E2,$E$2698:$H$3009,4,FALSE) -> 44470
C3: ASSESSORIA | D3: OLIVEIRA E PERES - parte | E3: 44470 | F3: 3135 | G3: Empresa 1 | H3: =VLOOKUP(E3,$E$2698:$H$3009,4,FALSE) -> 44470
C4: MANUTENCAO | D4: TECNOFAST | E4: 44470 | F4: 145.55 | G4: Empresa 1 | H4: =VLOOKUP(E4,$E$2698:$H$3009,4,FALSE) -> 44470
C5: SOCIOS | D5: LUIS b | E5: 44470 | F5: 1000 | G5: Distribuição de Lucros | H5: =VLOOKUP(E5,$E$2698:$H$3009,4,FALSE) -> 44470
C6: EPI | D6: M JU | E6: 44470 | F6: 184.6 | G6: Empresa 2 | H6: =VLOOKUP(E6,$E$2698:$H$3009,4,FALSE) -> 44470
C7: ENCARGOS | D7: JUNTA COML - livro diario - Visao | E7: 44470 | F7: 26.33 | G7: Empresa 2 | H7: =VLOOKUP(E7,$E$2698:$H$3009,4,FALSE) -> 44470
C8: ALIMENTACAO | D8: RODRIGO CARDOSO - IRMAOS DA FRONTEIRA - vcto 11/09 | E8: 44471 | F8: 170.9 | G8: Empresa 2 | H8: =VLOOKUP(E8,$E$2698:$H$3009,4,FALSE) -> 44473
C9: SOCIOS | D9: CASAS PAGLIARIN - VCTO 18/07 - sem falta cartorio | E9: 44472 | F9: 2046.92 | G9: Distribuição de Lucros | H9: =VLOOKUP(E9,$E$2698:$H$3009,4,FALSE) -> 44473
C10: PARCELAMENTO | D10: EMPRESTIMO FOLHA BB - 10/30 | E10: 44473 | F10: 2256.05 | G10: Empresa 2 | H10: =VLOOKUP(E10,$E$2698:$H$3009,4,FALSE) -> 44473
C11: TRANSPORTE | D11: VISATE- 20 cartoes | E11: 44473 | F11: 380 | G11: Empresa 2 | H11: =VLOOKUP(E11,$E$2698:$H$3009,4,FALSE) -> 44473
C12: EPI | D12: MAJUSEG | E12: 44474 | F12: 173.76 | G12: Empresa 2 | H12: =VLOOKUP(E12,$E$2698:$H$3009,4,FALSE) -> 44474
C13: SOCIOS | D13: LUIS b | E13: 44474 | F13: 500 | G13: Empresa 2 | H13: =VLOOKUP(E13,$E$2698:$H$3009,4,FALSE) -> 44474
C14: COMUNICACAO | D14: NET - vcto 20/09 (corte em 13/10) | E14: 44475 | F14: 206.95 | G14: Empresa 2 | H14: =VLOOKUP(E14,$E$2698:$H$3009,4,FALSE) -> 44475
... C20: ENCARGOS | D20: FGTS | E20: 44476 | F20: 783.61 | G20: Empresa 1 | H20: =VLOOKUP(E20,$E$2698:$H$3009,4,FALSE) -> 44476
C21: FÉRIAS | D21: PAOLA GOMES CAMINHA - vcto 09/09/21 - saldo | E21: 44476 | F21: =824-400 -> 424 | G21: Empresa 2 | H21: =VLOOKUP(E21,$E$2698:$H$3009,4,FALSE) -> 44476
C22: RESCISAO | D22: LUCINARA BENITES - SINDICATO | E22: 44476 | F22: 525.02 | G22: Empresa 2 | H22: =VLOOKUP(E22,$E$2698:$H$3009,4,FALSE) -> 44476
C23: COMBUSTIVEL | D23: FLAVIO | E23: 44476 | F23: 100 | G23: Empresa 2 | H23: =VLOOKUP(E23,$E$2698:$H$3009,4,FALSE) -> 44476
C24: VIAGEM | D24: JOEL - CAIXINHA - 01/03 | E24: 44476 | F24: 1811 | G24: Empresa 2 | H24: =VLOOKUP(E24,$E$2698:$H$3009,4,FALSE) -> 44476
C25: RESCISAO | D25: DANIEL TEIXEIRA - LIBRELATO | E25: 44476 | F25: 520.65 | G25: Empresa 2 | H25: =VLOOKUP(E25,$E$2698:$H$3009,4,FALSE) -> 44476
C26: VIAGEM | D26: VOB HOTEL - vcto 04/10 - já prorrogado (ultimo prazo antes do cartorio) | E26: 44477 | F26: 452 | G26: Empresa 2 | H26: =VLOOKUP(E26,$E$2698:$H$3009,4,FALSE) -> 44477
C27: SALARIOS | D27: SALARIOS - LIRANE e GUSTAVO (seguranca) | E27: 44477 | F27: =3625+3159 -> 6784 | G27: Empresa 2 | H27: =VLOOKUP(E27,$E$2698:$H$3009,4,FALSE) -> 44477
C28: SALARIOS | D28: SALARIOS - Antonio/ Volare - parte | E28: 44477 | F28: 1000 | G28: Empresa 2 | H28: =VLOOKUP(E28,$E$2698:$H$3009,4,FALSE) -> 44477
C29: ACORDO | D29: BRUNO DE SOUZA - 01/04 | E29: 44477 | F29: 1504.26 | G29: Empresa 2 | H29: =VLOOKUP(E29,$E$2698:$H$3009,4,FALSE) -> 44477
C30: EPI | D30: JUSTINA - vcto 19/09 - já prorrogado | E30: 44477 | F30: 787.5 | G30: Empresa 2 | H30: =VLOOKUP(E30,$E$2698:$H$3009,4,FALSE) -> 44477
C31: SOCIOS | D31: SEGURO LUIS b - STRADA | E31: 44477 | F31: 246.8 | G31: Distribuição de Lucros | H31: =VLOOKUP(E31,$E$2698:$H$3009,4,FALSE) -> 44477
C32: ALIMENTACAO | D32: ZAPAROLLI - PARTE (vcto 30/09) - não atende se não pagar | E32: 44477 | F32: 3000 | G32: Empresa 2 | H32: =VLOOKUP(E32,$E$2698:$H$3009,4,FALSE) -> 44477
C33: ALUGUEL | D33: MARCIO | E33: 44477 | F33: 950 | G33: Empresa 2 | H33: =VLOOKUP(E33,$E$2698:$H$3009,4,FALSE) -> 44477
C34: VIAGEM | D34: VOB HOTEL - vcto 13/09 | E34: 44477 | F34: =224+460 -> 684 | G34: Empresa 2 | H34: =VLOOKUP(E34,$E$2698:$H$3009,4,FALSE) -> 44477
C35: EPI | D35: MARCIO - 20 MASCARAS | E35: 44477 | F35: 90 | G35: Empresa 2 | H35: =VLOOKUP(E35,$E$2698:$H$3009,4,FALSE) -> 44477
C36: SALARIOS | D36: CHEQUES SALARIOS | E36: 44478 | F36: =658+629+91 -> 1378 | G36: Empresa 2 | H36: =VLOOKUP(E36,$E$2698:$H$3009,4,FALSE) -> 44480
C37: ENCARGOS | D37: GUIA SINDICATO - agendado | E37: 44480 | F37: 30 | G37: Empresa 2 | H37: =VLOOKUP(E37,$E$2698:$H$3009,4,FALSE) -> 44480
E38: 44481 | F38: 0 | G38: Empresa 2 | H38: =VLOOKUP(E38,$E$2698:$H$3009,4,FALSE) -> 44481
C39: SALARIOS | D39: CHEQUES SALARIOS | E39: 44482 | F39: =1288+424 -> 1712 | G39: Empresa 2 | H39: =VLOOKUP(E39,$E$2698:$H$3009,4,FALSE) -> 44482
C40: SALARIOS | D40: SALARIOS - Antonio (saldo)/Cristine/Romildo/Jose Luis/Joel (parte) - Volare | E40: 44482 | F40: =1075+1260+1876+2587+2000 -> 8798 | G40: Empresa 2 | H40: =VLOOKUP(E40,$E$2698:$H$3009,4,FALSE) -> 44482
C41: SALARIOS | D41: SALARIOS - Flavio/Nelci/Fabiana | E41: 44482 | F41: =3139+4550+3175 -> 10864 | G41: Empresa 2 | H41: =VLOOKUP(E41,$E$2698:$H$3009,4,FALSE) -> 44482
C42: COMUNICACAO | D42: CLARO - vcto 20/09 (corte em 14/10) | E42: 44482 | F42: =44.11+1283.39+189.39 -> 1516.89 | G42: Empresa 1 | H42: =VLOOKUP(E42,$E$2698:$H$3009,4,FALSE) -> 44482
C43: EPI | D43: MAJUSEG - vcto 04/10 | E43: 44482 | F43: 1037.97 | G43: Empresa 2 | H43: =VLOOKUP(E43,$E$2698:$H$3009,4,FALSE) -> 44482
C44: TERCEIROS | D44: GT3 - vcto 20/09 - já prorrogado | E44: 44482 | F44: 903.27 | G44: Empresa 2 | H44: =VLOOKUP(E44,$E$2698:$H$3009,4,FALSE) -> 44482
C45: ACORDO | D45: JURIDICO marco 01/03 | E45: 44482 | F45: 3390 | G45: Empresa 1 | H45: =VLOOKUP(E45,$E$2698:$H$3009,4,FALSE) -> 44482
...

Sheet Fluxo_10_21
B1: =IF(B5=1,"Domingo",IF(B5=2,"Segunda",IF(B5=3,"Terça",IF(B5=4,"Quarta",IF(B5=5,"Quinta",IF(B5=6,"Sexta",IF(B5=7,"Sábado",0))))))) -> Sexta | C1: =IF(C5=1,"Domingo",IF(C5=2,"Segunda",IF(C5=3,"Terça",IF(C5=4,"Quarta",IF(C5=5,"Quinta",IF(C5=6,"Sexta",IF(C5=7,"Sábado",0))))))) -> Segunda | D1: =IF(D5=1,"Domingo",IF(D5=2,"Segunda",IF(D5=3,"Terça",IF(D5=4,"Quarta",IF(D5=5,"Quinta",IF(D5=6,"Sexta",IF(D5=7,"Sábado",0))))))) -> Terça | E1: =IF(E5=1,"Domingo",IF(E5=2,"Segunda",IF(E5=3,"Terça",IF(E5=4,"Quarta",IF(E5=5,"Quinta",IF(E5=6,"Sexta",IF(E5=7,"Sábado",0))))))) -> Quarta | F1: =IF(F5=1,"Domingo",IF(F5=2,"Segunda",IF(F5=3,"Terça",IF(F5=4,"Quarta",IF(F5=5,"Quinta",IF(F5=6,"Sexta",IF(F5=7,"Sábado",0))))))) -> Quinta | G1: =IF(G5=1,"Domingo",IF(G5=2,"Segunda",IF(G5=3,"Terça",IF(G5=4,"Quarta",IF(G5=5,"Quinta",IF(G5=6,"Sexta",IF(G5=7,"Sábado",0))))))) -> Sexta | H1: =IF(H5=1,"Domingo",IF(H5=2,"Segunda",IF(H5=3,"Terça",IF(H5=4,"Quarta",IF(H5=5,"Quinta",IF(H5=6,"Sexta",IF(H5=7,"Sábado",0))))))) -> Segunda | I1: =IF(I5=1,"Domingo",IF(I5=2,"Segunda",IF(I5=3,"Terça",IF(I5=4,"Quarta",IF(I5=5,"Quinta",IF(I5=6,"Sexta",IF(I5=7,"Sábado",0))))))) -> Terça | ... V1: =IF(V5=1,"Domingo",IF(V5=2,"Segunda",IF(V5=3,"Terça",IF(V5=4,"Quarta",IF(V5=5,"Quinta",IF(V5=6,"Sexta",IF(V5=7,"Sábado",0))))))) -> Sexta
A2: Localizado no banco | B2: =B29 -> 44470 | C2: =C29 -> 44473 | D2: =D29 -> 44474 | E2: =E29 -> 44475 | F2: =F29 -> 44476 | G2: =G29 -> 44477 | H2: =H29 -> 44480 | I2: =I29 -> 44481 | ... V2: =V29 -> 44498
A4: SALDO INICIAL | B4: =Fluxo_09_21!W38 -> -19248.832 | C4: =B38 -> -1729.892 | D4: =C38 -> -4625.792 | E4: =D38 -> -5299.552 | F4: =E38 -> -21425.812 | G4: =F38 -> -21369.282 | H4: =G38 -> -21931.592 | I4: =H38 -> 11806.548 | J4: =I38 -> 11806.548 | ... V4: =U38 -> -13130.702
B5: =WEEKDAY(B2) -> 6 | C5: =WEEKDAY(C2) -> 2 | D5: =WEEKDAY(D2) -> 3 | E5: =WEEKDAY(E2) -> 4 | F5: =WEEKDAY(F2) -> 5 | G5: =WEEKDAY(G2) -> 6 | H5: =WEEKDAY(H2) -> 2 | I5: =WEEKDAY(I2) -> 3 | ... V5: =WEEKDAY(V2) -> 6
A6: RECEBIMENTOS (OPERAÇÃO) | B6: =SUM(B7:B26) -> 26005.56 | C6: =SUM(C7:C26) -> 1957.97 | D6: =SUM(D7:D26) -> 0 | E6: =SUM(E7:E26) -> 43000 | F6: =SUM(F7:F26) -> 4220.81 | G6: =SUM(G7:G26) -> 14936.25 | H6: =SUM(H7:H26) -> 35146.14 | I6: =SUM(I7:I26) -> 0 | ... V6: =SUM(V7:V26) -> 9111
A7: MARCOPOLO/SEMAN | B7: =2254.02+9664.2+11747.84-370.5 -> 23295.56 | C7: =1957.97 -> 1957.97 | G7: 5215.35 | H7: =24319.05 -> 24319.05 | R7: 13063.05 | V7: =9681-570 -> 9111
A8: MARCOPOLO | G8: 9720.9
A9: VOLARE | H9: =3300+1583 -> 4883 | P9: 1736 | R9: 45058
A10: HIDROVER | J10: =7338.24+1834.56 -> 9172.8 | R10: 2800
A11: WSUL
A12: RUGERI | B12: 2710 | J12: 2878.38
A13: CIFERAL
A14: SAN MARINO | F14: 4220.81 | H14: 5944.09 | R14: 6416.88
A15: LIBRELATO | J15: =2258.82+3822.62+5903.14+6693.45+2258.14+6050.14 -> 26986.31 | T15: 14588.44
A16: FLORENSE | J16: 4789.85
A17: OLIMPIA | E17: 43000 | J17: -43000 | L17: 4000 | O17: 10010 | Q17: 20000
A18: RENOVAR | N18: 1500 | U18: 3200
A27: PAGAMENTOS PROGRAMADOS
A28: Soma de Valor | B28: Pagto.
A29: tipo | B29: 44470 | C29: 44473 | D29: 44474 | E29: 44475 | F29: 44476 | G29: 44477 | H29: 44480 | I29: 44481 | J29: 44482 | K29: 44483 | L29: 44484 | M29: 44487 | N29: 44488 | O29: 44489 | P29: 44490 | Q29: 44491 | R29: 44494 | S29: 44495 | T29: 44496 | U29: 44497 | V29: 44498 | W29: Total Geral
A30: PARTICULAR | B30: 1000 | C30: 2046.92 | E30: 2032.81 | G30: 246.8 | L30: 415.09 | M30: 2505 | O30: 84.73 | R30: 300 | V30: 1020.5 | W30: 9651.85
A31: VENTURE | B31: 7275.69 | F31: 783.61 | J31: 4906.89 | O31: 2597.36 | P31: 2010 | Q31: 265.57 | R31: 36629.35 | V31: 1291.59 | W31: 55760.06
A32: PKS | Q32: 91.05 | W32: 91.05
A33: SEMAN | B33: 210.93 | C33: 2806.95 | D33: 673.76 | E33: 57093.45 | F33: 3380.67 | G33: 15251.76 | H33: 1408 | I33: 0 | J33: 23315.24 | K33: 5705.9 | L33: 1664.83 | M33: 1057.95 | N33: 1422.75 | O33: 6173.14 | P33: 943.41 | Q33: 17905.71 | R33: 18500.59 | S33: 1642.4 | T33: 0 | U33: 20000 | V33: 10730.39 | W33: 189887.83
A34: Total Geral | B34: 8486.62 | C34: 4853.87 | D34: 673.76 | E34: 59126.26 | F34: 4164.28 | G34: 15498.56 | H34: 1408 | I34: 0 | J34: 28222.13 | K34: 5705.9 | L34: 2079.92 | M34: 3562.95 | N34: 1422.75 | O34: 8855.23 | P34: 2953.41 | Q34: 18262.33 | R34: 55429.94 | S34: 1642.4 | T34: 0 | U34: 20000 | V34: 13042.48 | W34: 255390.79
A38: SALDO FINAL | B38: =B4+B6-GETPIVOTDATA("Valor",$A$28,"Pagto.",DATE(2021,10,1)) -> -1729.892 | C38: =C4+C6-GETPIVOTDATA("Valor",$A$28,"Pagto.",DATE(2021,10,4)) -> -4625.792 | D38: =D4+D6-GETPIVOTDATA("Valor",$A$28,"Pagto.",DATE(2021,10,5)) -> -5299.552 | E38: =E4+E6-GETPIVOTDATA("Valor",$A$28,"Pagto.",DATE(2021,10,6)) -> -21425.812 | F38: =F4+F6-GETPIVOTDATA("Valor",$A$28,"Pagto.",DATE(2021,10,7)) -> -21369.282 | G38: =G4+G6-GETPIVOTDATA("Valor",$A$28,"Pagto.",DATE(2021,10,8)) -> -21931.592 | H38: =H4+H6-GETPIVOTDATA("Valor",$A$28,"Pagto.",DATE(2021,10,11)) -> 11806.548 | I38: =I4+I6-GETPIVOTDATA("Valor",$A$28,"Pagto.",DATE(2021,10,12)) -> 11806.548 | J38: =J4+J6-GETPIVOTDATA("Valor",$A$28,"Pagto.",DATE(2021,10,13)) -> -15588.242 | K38: =K4+K6-GETPIVOTDATA("Valor",$A$28,"Pagto.",DATE(2021,10,14)) -> -21294.142 | L38: =L4+L6-GETPIVOTDATA("Valor",$A$28,"Pagto.",DATE(2021,10,15)) -> -19374.062 | M38: =M4+M6-GETPIVOTDATA("Valor",$A$28,"Pagto.",DATE(2021,10,18)) -> -22937.012 | N38: =N4+N6-GETPIVOTDATA("Valor",$A$28,"Pagto.",DATE(2021,10,19)) -> -22859.762 | O38: =O4+O6-GETPIVOTDATA("Valor",$A$28,"Pagto.",DATE(2021,10,20)) -> -21704.992 | P38: =P4+P6-GETPIVOTDATA("Valor",$A$28,"Pagto.",DATE(2021,10,21)) -> -22922.402 | Q38: =Q4+Q6-GETPIVOTDATA("Valor",$A$28,"Pagto.",DATE(2021,10,22)) -> -21184.732 | R38: =R4+R6-GETPIVOTDATA("Valor",$A$28,"Pagto.",DATE(2021,10,25)) -> -9276.742 | S38: =S4+S6-GETPIVOTDATA("Valor",$A$28,"Pagto.",DATE(2021,10,26)) -> -10919.142 | T38: =T4+T6-GETPIVOTDATA("Valor",$A$28,"Pagto.",DATE(2021,10,27)) -> 3669.298 | U38: =U4+U6-GETPIVOTDATA("Valor",$A$28,"Pagto.",DATE(2021,10,28)) -> -13130.702 | V38: =V4+V6-GETPIVOTDATA("Valor",$A$28,"Pagto.",DATE(2021,10,29)) -> -17062.182

Sheet 09_21
A1: 0 | B1: tm | C1: CodCli | D1: Nome | E1: dtvcto | F1: Valor | G1: tipo | H1: Pagto.
C2: BANCOS | D2: JUROS E DESP BANCARIAS | E2: 44440 | F2: =2197.64+250+485+200.64 -> 3133.28 | G2: Empresa 1 | H2: =VLOOKUP(E2,$E$2760:$H$2817,4,FALSE) -> 44440
C3: EPI | D3: ZAPA - vcto 17/08 - sem falta - boleto já prorrogado | E3: 44440 | F3: 589.88 | G3: Empresa 2 | H3: =VLOOKUP(E3,$E$2760:$H$2817,4,FALSE) -> 44440
C4: EPI | D4: ZAPA - vcto 19/08 - sem falta - boleto já prorrogado | E4: 44440 | F4: 251.83 | G4: Empresa 2 | H4: =VLOOKUP(E4,$E$2760:$H$2817,4,FALSE) -> 44440
C5: SALARIOS | D5: ARQUIVO - parte | E5: 44440 | F5: =26842+154+578+2000 -> 29574 | G5: Empresa 2 | H5: =VLOOKUP(E5,$E$2760:$H$2817,4,FALSE) -> 44440
C6: RESCISAO | D6: FGTS RESCISORIO ALISSON FRANCISCONI - LIBRELATO | E6: 44440 | F6: 26.82 | G6: Empresa 2 | H6: =VLOOKUP(E6,$E$2760:$H$2817,4,FALSE) -> 44440
C7: ALIMENTACAO | D7: ZAPAROLI - vcto 30/08 - parcelado em 3 vezes (01/03) | E7: 44440 | F7: 2000 | G7: Empresa 2 | H7: =VLOOKUP(E7,$E$2760:$H$2817,4,FALSE) -> 44440
C8: COMBUSTIVEL | D8: UNO FLAVIO | E8: 44441 | F8: 50 | G8: Empresa 2 | H8: =VLOOKUP(E8,$E$2760:$H$2817,4,FALSE) -> 44441
C9: COMBUSTIVEL | D9: UNO CLEBER | E9: 44441 | F9: 50 | G9: Empresa 2 | H9: =VLOOKUP(E9,$E$2760:$H$2817,4,FALSE) -> 44441
C10: MATERIAL | D10: PERINI | E10: 44441 | F10: 92 | G10: Empresa 2 | H10: =VLOOKUP(E10,$E$2760:$H$2817,4,FALSE) -> 44441
C11: SALARIOS | D11: ARQUIVO - parte | E11: 44441 | F11: =7939+2110 -> 10049 | G11: Empresa 2 | H11: =VLOOKUP(E11,$E$2760:$H$2817,4,FALSE) -> 44441
C12: EPI | D12: CORSUL | E12: 44441 | F12: 97.2 | G12: Empresa 2 | H12: =VLOOKUP(E12,$E$2760:$H$2817,4,FALSE) -> 44441
C13: SOCIOS | D13: VIVO - LUIS - vcto 26/08 | E13: 44442 | F13: 80.99 | G13: Distribuição de Lucros | H13: =VLOOKUP(E13,$E$2760:$H$2817,4,FALSE) -> 44442
C14: VIAGEM | D14: JOEL - CAIXINHA | E14: 44442 | F14: 3000 | G14: Empresa 2 | H14: =VLOOKUP(E14,$E$2760:$H$2817,4,FALSE) -> 44442
C15: VIAGEM | D15: FLAVIO | E15: 44442 | F15: 415 | G15: Empresa 2 | H15: =VLOOKUP(E15,$E$2760:$H$2817,4,FALSE) -> 44442
C16: COMBUSTIVEL | D16: CLEBER | E16: 44442 | F16: 150 | G16: Empresa 2 | H16: =VLOOKUP(E16,$E$2760:$H$2817,4,FALSE) -> 44442
C17: SOCIOS | D17: LUIS b | E17: 44442 | F17: 1000 | G17: Distribuição de Lucros | H17: =VLOOKUP(E17,$E$2760:$H$2817,4,FALSE) -> 44442
C18: SALARIOS | D18: SALARIOS - ARQUIVO | E18: 44442 | F18: =13092-2110 -> 10982 | G18: Empresa 2 | H18: =VLOOKUP(E18,$E$2760:$H$2817,4,FALSE) -> 44442
C19: EMPRESTIMO | D19: MONEO - parte | E19: 44442 | F19: 3000 | G19: Empresa 2 | H19: =VLOOKUP(E19,$E$2760:$H$2817,4,FALSE) -> 44442
C20: TRANSPORTE | D20: VAN - saldo - pagar em cheque | E20: 44442 | F20: =3863.5+1863.5-1000 -> 4727 | G20: Empresa 2 | H20: =VLOOKUP(E20,$E$2760:$H$2817,4,FALSE) -> 44442
C21: PARCELAMENTO | D21: EMPRESTIMO FOLHA BB - 09/30 e 10/30 | E21: 44443 | F21: 4465.85 | G21: Empresa 2 | H21: =VLOOKUP(E21,$E$2760:$H$2817,4,FALSE) -> 44445
C22: ENCARGOS | D22: FGTS (combinado com Geise, não atrasar) | E22: 44445 | F22: 793.15 | G22: Empresa 1 | H22: =VLOOKUP(E22,$E$2760:$H$2817,4,FALSE) -> 44445
C23: SALARIOS | D23: GEAN e IGOR (VOLARE) | E23: 44445 | F23: =2222+2848 -> 5070 | G23: Empresa 2 | H23: =VLOOKUP(E23,$E$2760:$H$2817,4,FALSE) -> 44445
C24: FÉRIAS | D24: ADRIANA DA d - vcto 17/08 (saldo) | E24: 44446 | F24: 594 | G24: Empresa 2 | H24: =VLOOKUP(E24,$E$2760:$H$2817,4,FALSE) -> 44446
C25: FÉRIAS | D25: RUTIELI VIEIRA - vcto 30/07 | E25: 44447 | F25: 1032 | G25: Empresa 2 | H25: =VLOOKUP(E25,$E$2760:$H$2817,4,FALSE) -> 44447
C26: COMUNICACAO | D26: NET - vcto 20/08 (corte em 13/09) | E26: 44448 | F26: 215.85 | G26: Empresa 2 | H26: =VLOOKUP(E26,$E$2760:$H$2817,4,FALSE) -> 44448
C27: FÉRIAS | D27: KARINE BARBIERI - vcto 26/08 | E27: 44448 | F27: 843 | G27: Empresa 2 | H27: =VLOOKUP(E27,$E$2760:$H$2817,4,FALSE) -> 44448
C28: RESCISAO | D28: INGRIDI MACIEL DOS SANTOS | E28: 44448 | F28: 262.59 | G28: Empresa 2 | H28: =VLOOKUP(E28,$E$2760:$H$2817,4,FALSE) -> 44448
C29: SALARIOS | D29: SALARIOS - VOLARE | E29: 44448 | F29: 10835 | G29: Empresa 2 | H29: =VLOOKUP(E29,$E$2760:$H$2817,4,FALSE) -> 44448
C30: SALARIOS | D30: SALARIOS - secretaria Joel | E30: 44448 | F30: 928 | G30: Empresa 2 | H30: =VLOOKUP(E30,$E$2760:$H$2817,4,FALSE) -> 44448
C31: SALARIOS | D31: SALARIOS - CHEQUES | E31: 44448 | F31: =692+441+630 -> 1763 | G31: Empresa 2 | H31: =VLOOKUP(E31,$E$2760:$H$2817,4,FALSE) -> 44448
C32: INFORMATICA | D32: INFOCALL - vcto 10/08 | E32: 44449 | F32: 200 | G32: Empresa 1 | H32: =VLOOKUP(E32,$E$2760:$H$2817,4,FALSE) -> 44449
C33: VIAGEM | D33: FLAVIO | E33: 44449 | F33: 400 | G33: Empresa 2 | H33: =VLOOKUP(E33,$E$2760:$H$2817,4,FALSE) -> 44449
C34: RESCISAO | D34: RAFAEL SCARSI - FGTS RESCISORIO | E34: 44449 | F34: 9.25 | G34: Empresa 2 | H34: =VLOOKUP(E34,$E$2760:$H$2817,4,FALSE) -> 44449
C35: COMBUSTIVEL | D35: REEMBOLSAR RUBENS c (julho/agosto) | E35: 44449 | F35: 400 | G35: Distribuição de Lucros | H35: =VLOOKUP(E35,$E$2760:$H$2817,4,FALSE) -> 44449
C36: SALARIOS | D36: ADMIN - PARCIAL | E36: 44449 | F36: =1000+2673+2114+1000+1444+1000+1000+2000 -> 12231 | G36: Empresa 2 | H36: =VLOOKUP(E36,$E$2760:$H$2817,4,FALSE) -> 44449
C37: EPI | D37: JUSTINA - vcto 29/08 | E37: 44449 | F37: 900 | G37: Empresa 2 | H37: =VLOOKUP(E37,$E$2760:$H$2817,4,FALSE) -> 44449
C38: RESCISAO | D38: TIAGO DA d - Joel (vcto 18/08) | E38: 44449 | F38: =1555.98 -> 1555.98 | G38: Empresa 2 | H38: =VLOOKUP(E38,$E$2760:$H$2817,4,FALSE) -> 44449
C39: VIAGEM | D39: JOEL - CIFERAL | E39: 44449 | F39: 3000 | G39: Empresa 2 | H39: =VLOOKUP(E39,$E$2760:$H$2817,4,FALSE) -> 44449
C40: EXPEDIENTE | D40: LICEIS SUPRIMENTOS - vcto 26/08 | E40: 44449 | F40: 248.71 | G40: Empresa 2 | H40: =VLOOKUP(E40,$E$2760:$H$2817,4,FALSE) -> 44449
...

Sheet Fluxo_09_21
B1: =IF(B5=1,"Domingo",IF(B5=2,"Segunda",IF(B5=3,"Terça",IF(B5=4,"Quarta",IF(B5=5,"Quinta",IF(B5=6,"Sexta",IF(B5=7,"Sábado",0))))))) -> Quarta | C1: =IF(C5=1,"Domingo",IF(C5=2,"Segunda",IF(C5=3,"Terça",IF(C5=4,"Quarta",IF(C5=5,"Quinta",IF(C5=6,"Sexta",IF(C5=7,"Sábado",0))))))) -> Quinta | D1: =IF(D5=1,"Domingo",IF(D5=2,"Segunda",IF(D5=3,"Terça",IF(D5=4,"Quarta",IF(D5=5,"Quinta",IF(D5=6,"Sexta",IF(D5=7,"Sábado",0))))))) -> Sexta | E1: =IF(E5=1,"Domingo",IF(E5=2,"Segunda",IF(E5=3,"Terça",IF(E5=4,"Quarta",IF(E5=5,"Quinta",IF(E5=6,"Sexta",IF(E5=7,"Sábado",0))))))) -> Segunda | F1: =IF(F5=1,"Domingo",IF(F5=2,"Segunda",IF(F5=3,"Terça",IF(F5=4,"Quarta",IF(F5=5,"Quinta",IF(F5=6,"Sexta",IF(F5=7,"Sábado",0))))))) -> Terça | G1: =IF(G5=1,"Domingo",IF(G5=2,"Segunda",IF(G5=3,"Terça",IF(G5=4,"Quarta",IF(G5=5,"Quinta",IF(G5=6,"Sexta",IF(G5=7,"Sábado",0))))))) -> Quarta | H1: =IF(H5=1,"Domingo",IF(H5=2,"Segunda",IF(H5=3,"Terça",IF(H5=4,"Quarta",IF(H5=5,"Quinta",IF(H5=6,"Sexta",IF(H5=7,"Sábado",0))))))) -> Quinta | I1: =IF(I5=1,"Domingo",IF(I5=2,"Segunda",IF(I5=3,"Terça",IF(I5=4,"Quarta",IF(I5=5,"Quinta",IF(I5=6,"Sexta",IF(I5=7,"Sábado",0))))))) -> Sexta | ... W1: =IF(W5=1,"Domingo",IF(W5=2,"Segunda",IF(W5=3,"Terça",IF(W5=4,"Quarta",IF(W5=5,"Quinta",IF(W5=6,"Sexta",IF(W5=7,"Sábado",0))))))) -> Quinta
A2: Localizado no banco | B2: =B29 -> 44440 | C2: =C29 -> 44441 | D2: =D29 -> 44442 | E2: =E29 -> 44445 | F2: =F29 -> 44446 | G2: =G29 -> 44447 | H2: =H29 -> 44448 | I2: =I29 -> 44449 | ... W2: =W29 -> 44469
A4: SALDO INICIAL | B4: =Fluxo_08_21!W38 -> -6812.36 | C4: =B38 -> -11416.67 | D4: =C38 -> -3181.92 | E4: =D38 -> -8217.99 | F4: =E38 -> -18546.99 | G4: =F38 -> -19140.99 | H4: =G38 -> -20172.99 | I4: =H38 -> -10020.43 | J4: =I38 -> -6850.11 | ... W4: =V38 -> -14905.562
B5: =WEEKDAY(B2) -> 4 | C5: =WEEKDAY(C2) -> 5 | D5: =WEEKDAY(D2) -> 6 | E5: =WEEKDAY(E2) -> 2 | F5: =WEEKDAY(F2) -> 3 | G5: =WEEKDAY(G2) -> 4 | H5: =WEEKDAY(H2) -> 5 | I5: =WEEKDAY(I2) -> 6 | ... W5: =WEEKDAY(W2) -> 5
A6: RECEBIMENTOS (OPERAÇÃO) | B6: =SUM(B7:B26) -> 30971.5 | C6: =SUM(C7:C26) -> 18572.95 | D6: =SUM(D7:D26) -> 18318.92 | E6: =SUM(E7:E26) -> 0 | F6: =SUM(F7:F26) -> 0 | G6: =SUM(G7:G26) -> 0 | H6: =SUM(H7:H26) -> 25000 | I6: =SUM(I7:I26) -> 33247.25 | ... W6: =SUM(W7:W26) -> 0
A7: MARCOPOLO/SEMAN | B7: =11747+6318-125.08 -> 17939.92 | C7: 18572.95 | J7: 6526.1
A8: MARCOPOLO | B8: =13031.58 -> 13031.58
A9: VOLARE | D9: 4320.44 | T9: =4300+20200 -> 24500
A10: HIDROVER | L10: =7338.24+1834.56 -> 9172.8
A11: WSUL | I11: 2300
A12: RUGERI
A13: CIFERAL | I13: 30947.25 | N13: 20365.96
A14: SAN MARINO | D14: 9912.48
A15: LIBRELATO | J15: =5485.5+5372.25+6270.64+5372.25+5903.14 -> 28403.78 | T15: =3822.62+3974.81+4473.18+4473.18+6693.45 -> 23437.24
A16: ERZINGER - ES | D16: 1086
A17: CABEÇA | D17: 3000 | H17: =17000+8000 -> 25000 | J17: =130000-17000+35000 -> 148000 | K17: =8000 -> 8000
A18: FLORENSE | L18: =1764+5059.43+1628.39+2327.01 -> 10778.83
A19: RENOVAR | R19: 27000 | S19: 7000 | V19: 30000
A27: PAGAMENTOS PROGRAMADOS
A28: Soma de Valor | B28: Pagto.
A29: tipo | B29: 44440 | C29: 44441 | D29: 44442 | E29: 44445 | F29: 44446 | G29: 44447 | H29: 44448 | I29: 44449 | J29: 44452 | K29: 44453 | L29: 44454 | M29: 44455 | N29: 44456 | O29: 44459 | P29: 44460 | Q29: 44461 | R29: 44462 | S29: 44463 | T29: 44466 | U29: 44467 | V29: 44468 | W29: 44469 | X29: Total Geral
A30: PARTICULAR | D30: 1080.99 | I30: 400 | J30: 604.34 | K30: 460 | L30: 370 | N30: 4100 | T30: 4520 | V30: 2000 | X30: 13535.33
A31: VENTURE | B31: 3133.28 | E31: 793.15 | I31: 1727.33 | K31: 4200 | L31: 3038.44 | M31: 81.99 | N31: 2124.2 | Q31: 177 | R31: 110 | T31: 2925.03 | V31: 5834.71 | X31: 24145.13
A32: SOLUTEC | V32: 1283.09 | X32: 1283.09
A33: PKS | K33: 534.69 | T33: 3710.47 | X33: 4245.16
A34: SEMAN | B34: 32442.53 | C34: 10338.2 | D34: 22274 | E34: 9535.85 | F34: 594 | G34: 1032 | H34: 14847.44 | I34: 27949.6 | J34: 183358.58 | K34: 11259.3 | L34: 17945.662 | N34: 17707.57 | O34: 0 | P34: 664 | Q34: 380 | R34: 27119.32 | S34: 3541.22 | T34: 31955.81 | U34: 6350 | V34: 14884.74 | W34: 4343.27 | X34: 438523.09
A35: Total Geral | B35: 35575.81 | C35: 10338.2 | D35: 23354.99 | E35: 10329 | F35: 594 | G35: 1032 | H35: 14847.44 | I35: 30076.93 | J35: 183962.92 | K35: 16453.99 | L35: 21354.102 | M35: 81.99 | N35: 23931.77 | O35: 0 | P35: 664 | Q35: 557 | R35: 27229.32 | S35: 3541.22 | T35: 43111.31 | U35: 6350 | V35: 24002.54 | W35: 4343.27 | X35: 481731.8
A38: SALDO FINAL | B38: =B4+B6-GETPIVOTDATA("Valor",$A$28,"Pagto.",DATE(2021,9,1)) -> -11416.67 | C38: =C4+C6-GETPIVOTDATA("Valor",$A$28,"Pagto.",DATE(2021,9,2)) -> -3181.92 | D38: =D4+D6-GETPIVOTDATA("Valor",$A$28,"Pagto.",DATE(2021,9,3)) -> -8217.99 | E38: =E4+E6-GETPIVOTDATA("Valor",$A$28,"Pagto.",DATE(2021,9,6)) -> -18546.99 | F38: =F4+F6-GETPIVOTDATA("Valor",$A$28,"Pagto.",DATE(2021,9,7)) -> -19140.99 | G38: =G4+G6-GETPIVOTDATA("Valor",$A$28,"Pagto.",DATE(2021,9,8)) -> -20172.99 | H38: =H4+H6-GETPIVOTDATA("Valor",$A$28,"Pagto.",DATE(2021,9,9)) -> -10020.43 | I38: =I4+I6-GETPIVOTDATA("Valor",$A$28,"Pagto.",DATE(2021,9,10)) -> -6850.11 | J38: =J4+J6-GETPIVOTDATA("Valor",$A$28,"Pagto.",DATE(2021,9,13)) -> -7883.15 | K38: =K4+K6-GETPIVOTDATA("Valor",$A$28,"Pagto.",DATE(2021,9,14)) -> -16337.14 | L38: =L4+L6-GETPIVOTDATA("Valor",$A$28,"Pagto.",DATE(2021,9,15)) -> -17739.612 | M38: =M4+M6-GETPIVOTDATA("Valor",$A$28,"Pagto.",DATE(2021,9,16)) -> -17821.602 | N38: =N4+N6-GETPIVOTDATA("Valor",$A$28,"Pagto.",DATE(2021,9,17)) -> -21387.412 | O38: =O4+O6-GETPIVOTDATA("Valor",$A$28,"Pagto.",DATE(2021,9,20)) -> -21387.412 | P38: =P4+P6-GETPIVOTDATA("Valor",$A$28,"Pagto.",DATE(2021,9,21)) -> -22051.412 | Q38: =Q4+Q6-GETPIVOTDATA("Valor",$A$28,"Pagto.",DATE(2021,9,22)) -> -22608.412 | R38: =R4+R6-GETPIVOTDATA("Valor",$A$28,"Pagto.",DATE(2021,9,23)) -> -22837.732 | S38: =S4+S6-GETPIVOTDATA("Valor",$A$28,"Pagto.",DATE(2021,9,24)) -> -19378.952 | T38: =T4+T6-GETPIVOTDATA("Valor",$A$28,"Pagto.",DATE(2021,9,27)) -> -14553.022 | U38: =U4+U6-GETPIVOTDATA("Valor",$A$28,"Pagto.",DATE(2021,9,28)) -> -20903.022 | V38: =V4+V6-GETPIVOTDATA("Valor",$A$28,"Pagto.",DATE(2021,9,29)) -> -14905.562 | W38: =W4+W6-GETPIVOTDATA("Valor",$A$28,"Pagto.",DATE(2021,9,30)) -> -19248.832

Sheet 08_21
A1: 0 | B1: tm | C1: CodCli | D1: Nome | E1: dtvcto | F1: Valor | G1: tipo | H1: Pagto.
C2: BANCOS | D2: JUROS E DESP BANCARIAS | E2: 44409 | F2: =2821.88+125+950+200+144+200+250+153+150 -> 4993.88 | G2: Empresa 1 | H2: =VLOOKUP(E2,$E$2588:$H$2910,4,FALSE) -> 44410
C3: VIAGEM | D3: VOB HOTEL | E3: 44409 | F3: 456 | G3: Empresa 2 | H3: =VLOOKUP(E3,$E$2588:$H$2910,4,FALSE) -> 44410
C4: COMBUSTIVEL | D4: TEONAS - MENSAL | E4: 44410 | F4: 150 | G4: Empresa 2 | H4: =VLOOKUP(E4,$E$2588:$H$2910,4,FALSE) -> 44410
C5: COMBUSTIVEL | D5: GENILSON - MENSAL | E5: 44410 | F5: 250 | G5: Empresa 2 | H5: =VLOOKUP(E5,$E$2588:$H$2910,4,FALSE) -> 44410
C6: CONSUMO | D6: DE TONI | E6: 44410 | F6: 32 | G6: Empresa 2 | H6: =VLOOKUP(E6,$E$2588:$H$2910,4,FALSE) -> 44410
C7: CONSUMO | D7: TONER FINANCEIRO | E7: 44410 | F7: 52 | G7: Empresa 2 | H7: =VLOOKUP(E7,$E$2588:$H$2910,4,FALSE) -> 44410
C8: TERCEIROS | D8: MARCIA - LIMPEZA | E8: 44411 | F8: 70 | G8: Empresa 2 | H8: =VLOOKUP(E8,$E$2588:$H$2910,4,FALSE) -> 44411
C9: RESCISAO | D9: FGTS RESCISORIO VALTER MUNHOZ | E9: 44411 | F9: 22.3 | G9: Empresa 2 | H9: =VLOOKUP(E9,$E$2588:$H$2910,4,FALSE) -> 44411
C10: CONSUMO | D10: DE TONI | E10: 44411 | F10: 243.67 | G10: Empresa 2 | H10: =VLOOKUP(E10,$E$2588:$H$2910,4,FALSE) -> 44411
C11: SALARIOS | D11: JAQUELINE NASCIMENTO (em dinheiro) | E11: 44411 | F11: 90 | G11: Empresa 2 | H11: =VLOOKUP(E11,$E$2588:$H$2910,4,FALSE) -> 44411
C12: PARCELAMENTO | D12: EMPRESTIMO FOLHA BB - 08/30 | E12: 44412 | F12: 2277.79 | G12: Empresa 2 | H12: =VLOOKUP(E12,$E$2588:$H$2910,4,FALSE) -> 44412
C13: SALARIOS | D13: EDUARDA CRISTINE - Librelato | E13: 44412 | F13: =12255-806-1609-200-1849-1843-429-1266-492-480-620-304-342-717-500-593 -> 205 | G13: Empresa 2 | H13: =VLOOKUP(E13,$E$2588:$H$2910,4,FALSE) -> 44412
C14: RESCISAO | D14: EDUARDA CRISTINE | E14: 44412 | F14: =219.15 -> 219.15 | G14: Empresa 2 | H14: =VLOOKUP(E14,$E$2588:$H$2910,4,FALSE) -> 44412
C15: TRANSPORTE | D15: 10 CARTOES | E15: 44413 | F15: 190 | G15: Empresa 1 | H15: =VLOOKUP(E15,$E$2588:$H$2910,4,FALSE) -> 44413
C16: COMUNICACAO | D16: NET - vcto 20/07 | E16: 44413 | F16: 194.02 | G16: Empresa 2 | H16: =VLOOKUP(E16,$E$2588:$H$2910,4,FALSE) -> 44413
C17: SALARIOS | D17: SALARIOS - ARQUIVO | E17: 44413 | F17: =52272-3607-556 -> 48109 | G17: Empresa 2 | H17: =VLOOKUP(E17,$E$2588:$H$2802,4,FALSE) -> 44413
C18: SALARIOS | D18: SALARIOS - volare (sem conta) | E18: 44413 | F18: 13730 | G18: Empresa 2 | H18: =VLOOKUP(E18,$E$2588:$H$2802,4,FALSE) -> 44413
C19: SALARIOS | D19: RUTIELE VIEIRA | E19: 44413 | F19: 851 | G19: Empresa 2 | H19: =VLOOKUP(E19,$E$2588:$H$2802,4,FALSE) -> 44413
C20: ENCARGOS | D20: FGTS | E20: 44414 | F20: 793.14 | G20: Empresa 1 | H20: =VLOOKUP(E20,$E$2588:$H$2802,4,FALSE) -> 44414
C21: SALARIOS | D21: FABIANE RODRIGUES | E21: 44414 | F21: 611 | G21: Empresa 2 | H21: =VLOOKUP(E21,$E$2588:$H$2802,4,FALSE) -> 44414
C22: PARCELAMENTO | D22: EMPRESTIMO FOLHA BB - 09/30 | E22: 44414 | F22: 2186.46 | G22: Empresa 2 | H22: =VLOOKUP(E22,$E$2588:$H$2802,4,FALSE) -> 44414
C23: COMBUSTIVEL | D23: CLEBER | E23: 44414 | F23: 150 | G23: Empresa 2 | H23: =VLOOKUP(E23,$E$2588:$H$2802,4,FALSE) -> 44414
C24: VIAGEM | D24: FLAVIO | E24: 44414 | F24: 640.73 | G24: Empresa 2 | H24: =VLOOKUP(E24,$E$2588:$H$2802,4,FALSE) -> 44414
C25: EXPEDIENTE | D25: KIPONTO | E25: 44414 | F25: 100 | G25: Empresa 1 | H25: =VLOOKUP(E25,$E$2588:$H$2802,4,FALSE) -> 44414
C26: SALARIOS | D26: GEAN SOARES DA d - VOLARE | E26: 44414 | F26: 2848 | G26: Empresa 2 | H26: =VLOOKUP(E26,$E$2588:$H$2802,4,FALSE) -> 44414
C27: SALARIOS | D27: DIF SALARIO RAFAEL | E27: 44414 | F27: 179 | G27: Empresa 2 | H27: =VLOOKUP(E27,$E$2588:$H$2802,4,FALSE) -> 44414
C28: EPI | D28: MAJUSEG - CHEQUE 08/07 | E28: 44414 | F28: 575.36 | G28: Empresa 2 | H28: =VLOOKUP(E28,$E$2588:$H$2802,4,FALSE) -> 44414
C29: IMPOSTOS | D29: ART ROGERIO MACEDO - ESTUFA marco | E29: 44415 | F29: 88.78 | G29: Empresa 1 | H29: =VLOOKUP(E29,$E$2588:$H$2802,4,FALSE) -> 44417
... C33: EPI | D33: MAJUSEG - vcto 05/08 | E33: 44417 | F33: 784.1 | G33: Empresa 2 | H33: =VLOOKUP(E33,$E$2588:$H$2802,4,FALSE) -> 44417
C34: SALARIOS | D34: SALARIOS - cheques | E34: 44417 | F34: =152+559+1811+564+991 -> 4077 | G34: Empresa 2 | H34: =VLOOKUP(E34,$E$2588:$H$2802,4,FALSE) -> 44417
C35: VIAGEM | D35: JOEL - CAIXINHA (fazer sem falta - troca pelo salario) | E35: 44417 | F35: 3000 | G35: Empresa 2 | H35: =VLOOKUP(E35,$E$2588:$H$2802,4,FALSE) -> 44417
C36: EPI | D36: MAJUSEG - CHEQUE 25/06 | E36: 44417 | F36: 895.48 | G36: Empresa 2 | H36: =VLOOKUP(E36,$E$2588:$H$2802,4,FALSE) -> 44417
C37: ALIMENTACAO | D37: RESTAURANTE ZAPAROLLI - saldo | E37: 44418 | F37: 3025 | G37: Empresa 2 | H37: =VLOOKUP(E37,$E$2588:$H$2802,4,FALSE) -> 44418
C38: ALIMENTACAO | D38: ALIMENTAR - NEOBUS - vcto 07/07 - sem falta, já prorrogado por duas vezes | E38: 44418 | F38: 1860.75 | G38: Empresa 2 | H38: =VLOOKUP(E38,$E$2588:$H$2802,4,FALSE) -> 44418
C39: SALARIOS | D39: SALARIOS - cheques | E39: 44418 | F39: =1300+468+556+152+265+374+525+435+158+333+333 -> 4899 | G39: Empresa 2 | H39: =VLOOKUP(E39,$E$2588:$H$2802,4,FALSE) -> 44418
C40: CURSO | D40: RAFAEL SCOPEL - parte entrada acordo | E40: 44418 | F40: 500 | G40: Empresa 2 | H40: =VLOOKUP(E40,$E$2588:$H$2802,4,FALSE) -> 44418
C41: SALARIOS | D41: CLEBER - parte (em dinheiro) | E41: 44418 | F41: 500 | G41: Empresa 2 | H41: =VLOOKUP(E41,$E$2588:$H$2802,4,FALSE) -> 44418
C42: SALARIOS | D42: GENILSON MENEZES | E42: 44418 | F42: 3607 | G42: Empresa 2 | H42: =VLOOKUP(E42,$E$2588:$H$2802,4,FALSE) -> 44418
C43: SALARIOS | D43: SALARIOS - cheques | E43: 44419 | F43: =167+167+160+601+505 -> 1600 | G43: Empresa 2 | H43: =VLOOKUP(E43,$E$2588:$H$2802,4,FALSE) -> 44419
...

Sheet Fluxo_08_21
B1: =IF(B5=1,"Domingo",IF(B5=2,"Segunda",IF(B5=3,"Terça",IF(B5=4,"Quarta",IF(B5=5,"Quinta",IF(B5=6,"Sexta",IF(B5=7,"Sábado",0))))))) -> Segunda | C1: =IF(C5=1,"Domingo",IF(C5=2,"Segunda",IF(C5=3,"Terça",IF(C5=4,"Quarta",IF(C5=5,"Quinta",IF(C5=6,"Sexta",IF(C5=7,"Sábado",0))))))) -> Terça | D1: =IF(D5=1,"Domingo",IF(D5=2,"Segunda",IF(D5=3,"Terça",IF(D5=4,"Quarta",IF(D5=5,"Quinta",IF(D5=6,"Sexta",IF(D5=7,"Sábado",0))))))) -> Quarta | E1: =IF(E5=1,"Domingo",IF(E5=2,"Segunda",IF(E5=3,"Terça",IF(E5=4,"Quarta",IF(E5=5,"Quinta",IF(E5=6,"Sexta",IF(E5=7,"Sábado",0))))))) -> Quinta | F1: =IF(F5=1,"Domingo",IF(F5=2,"Segunda",IF(F5=3,"Terça",IF(F5=4,"Quarta",IF(F5=5,"Quinta",IF(F5=6,"Sexta",IF(F5=7,"Sábado",0))))))) -> Sexta | G1: =IF(G5=1,"Domingo",IF(G5=2,"Segunda",IF(G5=3,"Terça",IF(G5=4,"Quarta",IF(G5=5,"Quinta",IF(G5=6,"Sexta",IF(G5=7,"Sábado",0))))))) -> Segunda | H1: =IF(H5=1,"Domingo",IF(H5=2,"Segunda",IF(H5=3,"Terça",IF(H5=4,"Quarta",IF(H5=5,"Quinta",IF(H5=6,"Sexta",IF(H5=7,"Sábado",0))))))) -> Terça | I1: =IF(I5=1,"Domingo",IF(I5=2,"Segunda",IF(I5=3,"Terça",IF(I5=4,"Quarta",IF(I5=5,"Quinta",IF(I5=6,"Sexta",IF(I5=7,"Sábado",0))))))) -> Quarta | ... W1: =IF(W5=1,"Domingo",IF(W5=2,"Segunda",IF(W5=3,"Terça",IF(W5=4,"Quarta",IF(W5=5,"Quinta",IF(W5=6,"Sexta",IF(W5=7,"Sábado",0))))))) -> Terça
A2: Localizado no banco | B2: =B29 -> 44410 | C2: =C29 -> 44411 | D2: =D29 -> 44412 | E2: =E29 -> 44413 | F2: =F29 -> 44414 | G2: =G29 -> 44417 | H2: =H29 -> 44418 | I2: =I29 -> 44419 | ... W2: =W29 -> 44439
A4: SALDO INICIAL | B4: =Fluxo_07_21!W38 -> -1710.84 | C4: =B38 -> -2323.44 | D4: =C38 -> 29175.31 | E4: =D38 -> 26473.37 | F4: =E38 -> -17952.29 | G4: =F38 -> -24716.75 | H4: =G38 -> -21034.38 | I4: =H38 -> -16601.52 | J4: =I38 -> -18291.52 | ... W4: =V38 -> -5631.99
B5: =WEEKDAY(B2) -> 2 | C5: =WEEKDAY(C2) -> 3 | D5: =WEEKDAY(D2) -> 4 | E5: =WEEKDAY(E2) -> 5 | F5: =WEEKDAY(F2) -> 6 | G5: =WEEKDAY(G2) -> 2 | H5: =WEEKDAY(H2) -> 3 | I5: =WEEKDAY(I2) -> 4 | ... W5: =WEEKDAY(W2) -> 3
A6: RECEBIMENTOS (OPERAÇÃO) | B6: =SUM(B7:B26) -> 5321.28 | C6: =SUM(C7:C26) -> 31924.72 | D6: =SUM(D7:D26) -> 0 | E6: =SUM(E7:E26) -> 18648.36 | F6: =SUM(F7:F26) -> 1319.23 | G6: =SUM(G7:G26) -> 13296.57 | H6: =SUM(H7:H26) -> 18824.61 | I6: =SUM(I7:I26) -> 0 | ... W6: =SUM(W7:W26) -> 0
A7: MARCOPOLO/SEMAN | B7: =5873.92-836 -> 5037.92 | C7: =13414.8+11747.84+6762.08 -> 31924.72 | E7: =12534.9-256.54 -> 12278.36 | G7: =11826.15 -> 11826.15 | J7: 2630.35 | K7: =1564+1936 -> 3500 | M7: 12627.03
A8: MARCOPOLO | F8: 1319.23 | L8: 968.1 | O8: 5799.63
A9: VOLARE | E9: =590+5780 -> 6370 | J9: 33251.91 | R9: 29145.19
A10: HIDROVER | T10: =7338.24+1834.56 -> 9172.8
A11: WSUL
A12: RUGERI | B12: 283.36 | G12: 1470.42 | K12: =1600.07 -> 1600.07 | Q12: 530.18 | V12: 1859.27
A13: CIFERAL
A14: SAN MARINO | K14: 4996.98 | M14: 4210.55 | V14: 6850.35
A15: LIBRELATO | K15: =3853.14+4473.18+3271.14+3853.14 -> 15450.6 | U15: =5782.25+5903.14 -> 11685.39
A16: FLORENSE | H16: =1607.81+4233.6+12983.2 -> 18824.61
A17: Previsao Estufa | Q17: 1320 | R17: -1320 | U17: 11587.18
A18: RENOVAR
A27: PAGAMENTOS PROGRAMADOS
A28: Soma de Valor | B28: Pagto.
A29: tipo | B29: 44410 | C29: 44411 | D29: 44412 | E29: 44413 | F29: 44414 | G29: 44417 | H29: 44418 | I29: 44419 | J29: 44420 | K29: 44421 | L29: 44424 | M29: 44425 | N29: 44426 | O29: 44427 | P29: 44428 | Q29: 44431 | R29: 44432 | S29: 44433 | T29: 44434 | U29: 44435 | V29: 44438 | W29: 44439 | X29: Total Geral
A30: PARTICULAR | K30: 2300 | M30: 2500 | T30: 3550 | U30: 1120 | X30: 9470
A31: VENTURE | B31: 4993.88 | E31: 190 | F31: 893.14 | G31: 308.78 | I31: 90 | J31: 2338.9 | K31: 564.56 | L31: 175.95 | M31: 2114.38 | Q31: 63.8 | R31: 9821 | U31: 1907.48 | X31: 23461.87
A32: SOLUTEC | U32: 1283.09 | X32: 1283.09
A33: PKS | L33: 534.69 | U33: 3710.47 | X33: 4245.16
A34: SEMAN | B34: 940 | C34: 425.97 | D34: 2701.94 | E34: 62884.02 | F34: 7190.55 | G34: 9305.42 | H34: 14391.75 | I34: 1600 | J34: 34692.03 | K34: 13127.87 | L34: 5010 | M34: 7828.73 | N34: 42.65 | O34: 1380 | P34: 15395.08 | Q34: 2000.88 | R34: 3534 | S34: 13775.75 | T34: 4179.33 | U34: 9627 | V34: 628.41 | W34: 1180.37 | X34: 211841.75
A35: Total Geral | B35: 5933.88 | C35: 425.97 | D35: 2701.94 | E35: 63074.02 | F35: 8083.69 | G35: 9614.2 | H35: 14391.75 | I35: 1690 | J35: 37030.93 | K35: 15992.43 | L35: 5720.64 | M35: 12443.11 | N35: 42.65 | O35: 1380 | P35: 15395.08 | Q35: 2064.68 | R35: 13355 | S35: 13775.75 | T35: 7729.33 | U35: 17648.04 | V35: 628.41 | W35: 1180.37 | X35: 250301.87
A38: SALDO FINAL | B38: =B4+B6-GETPIVOTDATA("Valor",$A$28,"Pagto.",DATE(2021,8,2)) -> -2323.44 | C38: =C4+C6-GETPIVOTDATA("Valor",$A$28,"Pagto.",DATE(2021,8,3)) -> 29175.31 | D38: =D4+D6-GETPIVOTDATA("Valor",$A$28,"Pagto.",DATE(2021,8,4)) -> 26473.37 | E38: =E4+E6-GETPIVOTDATA("Valor",$A$28,"Pagto.",DATE(2021,8,5)) -> -17952.29 | F38: =F4+F6-GETPIVOTDATA("Valor",$A$28,"Pagto.",DATE(2021,8,6)) -> -24716.75 | G38: =G4+G6-GETPIVOTDATA("Valor",$A$28,"Pagto.",DATE(2021,8,9)) -> -21034.38 | H38: =H4+H6-GETPIVOTDATA("Valor",$A$28,"Pagto.",DATE(2021,8,10)) -> -16601.52 | I38: =I4+I6-GETPIVOTDATA("Valor",$A$28,"Pagto.",DATE(2021,8,11)) -> -18291.52 | J38: =J4+J6-GETPIVOTDATA("Valor",$A$28,"Pagto.",DATE(2021,8,12)) -> -19440.19 | K38: =K4+K6-GETPIVOTDATA("Valor",$A$28,"Pagto.",DATE(2021,8,13)) -> -9884.97 | L38: =L4+L6-GETPIVOTDATA("Valor",$A$28,"Pagto.",DATE(2021,8,16)) -> -14637.51 | M38: =M4+M6-GETPIVOTDATA("Valor",$A$28,"Pagto.",DATE(2021,8,17)) -> -10243.04 | N38: =N4+N6-GETPIVOTDATA("Valor",$A$28,"Pagto.",DATE(2021,8,18)) -> -10285.69 | O38: =O4+O6-GETPIVOTDATA("Valor",$A$28,"Pagto.",DATE(2021,8,19)) -> -5866.06 | P38: =P4+P6-GETPIVOTDATA("Valor",$A$28,"Pagto.",DATE(2021,8,20)) -> -21261.14 | Q38: =Q4+Q6-GETPIVOTDATA("Valor",$A$28,"Pagto.",DATE(2021,8,23)) -> -21475.64 | R38: =R4+R6-GETPIVOTDATA("Valor",$A$28,"Pagto.",DATE(2021,8,24)) -> -7005.45 | S38: =S4+S6-GETPIVOTDATA("Valor",$A$28,"Pagto.",DATE(2021,8,25)) -> -20781.2 | T38: =T4+T6-GETPIVOTDATA("Valor",$A$28,"Pagto.",DATE(2021,8,26)) -> -19337.73 | U38: =U4+U6-GETPIVOTDATA("Valor",$A$28,"Pagto.",DATE(2021,8,27)) -> -13713.2 | V38: =V4+V6-GETPIVOTDATA("Valor",$A$28,"Pagto.",DATE(2021,8,30)) -> -5631.99 | W38: =W4+W6-GETPIVOTDATA("Valor",$A$28,"Pagto.",DATE(2021,8,31)) -> -6812.36

Sheet 07_21
A1: 0 | B1: tm | C1: CodCli | D1: Nome | E1: dtvcto | F1: Valor | G1: tipo | H1: Pagto.
C2: BANCOS | D2: JUROS E DESPESAS BANCARIAS | E2: 44378 | F2: =2489.38+153+200+314.8+508.45 -> 3665.63 | G2: Empresa 1 | H2: =VLOOKUP(E2,$E$2723:$H$2937,4,FALSE) -> 44378
C3: ALIMENTACAO | D3: CRISTINE LANCHES - saldo (já prorrogado) | E3: 44379 | F3: 722.11 | G3: Empresa 2 | H3: =VLOOKUP(E3,$E$2723:$H$2937,4,FALSE) -> 44379
C4: EPI | D4: CORSUL | E4: 44379 | F4: 179.1 | G4: Empresa 2 | H4: =VLOOKUP(E4,$E$2723:$H$2937,4,FALSE) -> 44379
C5: INFORMATICA | D5: DIGISAM - vcto 14/07/20 (sem falta) | E5: 44379 | F5: 577 | G5: Empresa 1 | H5: =VLOOKUP(E5,$E$2723:$H$2937,4,FALSE) -> 44379
C6: ALIMENTACAO | D6: TIO JOAO - vcto 17/06 | E6: 44379 | F6: 1501.65 | G6: Empresa 2 | H6: =VLOOKUP(E6,$E$2723:$H$2937,4,FALSE) -> 44379
C7: EXPEDIENTE | D7: KIPONTO - cartao ponto - vcto 30/06 | E7: 44379 | F7: 102 | G7: Empresa 1 | H7: =VLOOKUP(E7,$E$2723:$H$2937,4,FALSE) -> 44379
C8: SOCIOS | D8: CASAS PAGLIARIN - VCTO 18/06 - TITULO JÁ PRORROGADO | E8: 44379 | F8: 1858.18 | G8: Distribuição de Lucros | H8: =VLOOKUP(E8,$E$2723:$H$2937,4,FALSE) -> 44379
C9: COMBUSTIVEL | D9: TEONAS - MENSAL (descontado dias de atestado) | E9: 44379 | F9: 60 | G9: Empresa 2 | H9: =VLOOKUP(E9,$E$2723:$H$2937,4,FALSE) -> 44379
C10: COMBUSTIVEL | D10: GENILSON - MENSAL (incluido o reembolso de 03 cartoes de 04 passagens) | E10: 44379 | F10: 300 | G10: Empresa 2 | H10: =VLOOKUP(E10,$E$2723:$H$2937,4,FALSE) -> 44379
C11: COMBUSTIVEL | D11: ROGERIO - REEMBOLSO | E11: 44379 | F11: 150 | G11: Empresa 2 | H11: =VLOOKUP(E11,$E$2723:$H$2937,4,FALSE) -> 44379
C12: COMBUSTIVEL | D12: CLEBER | E12: 44379 | F12: 100 | G12: Empresa 2 | H12: =VLOOKUP(E12,$E$2723:$H$2937,4,FALSE) -> 44379
C13: VIAGEM | D13: FLAVIO (reembolsar 12,00) | E13: 44379 | F13: 412 | G13: Empresa 2 | H13: =VLOOKUP(E13,$E$2723:$H$2937,4,FALSE) -> 44379
